Workbook
Name _14_July_2025: OrderLines!$G$3:$G$925
Name Branch: Feedback!$B$2:$B$221
Name Branch: Orders!$C$2:$C$361
Name Branch: OrderLines!$H$2:$H$925
Name Breakfast: OrderLines!$L$3:$L$925
Name Category: Menu!$C$2:$C$20
Name Category: OrderLines!$E$2:$E$925
Name Combination: OrderLines!$S$2:$S$925
Name ComboFlag: OrderLines!$N$2:$N$925
Name Comment: Feedback!$D$2:$D$221
Name CustomerType: Orders!$D$2:$D$361
Name Date: Feedback!$A$2:$A$221
Name Date: WasteLog!$A$2:$A$121
Name DiscountFlag: OrderLines!$O$2:$O$925
Name DiscountPct: Orders!$G$2:$G$361
Name DiscountPct: OrderLines!$I$2:$I$925
Name FoodCost: OrderLines!$U$2:$U$925
Name GM: OrderLines!$T$2:$T$925
Name Head_Office_Café: OrderLines!$H$3:$H$925
Name id: OrderLines!$X$34:$X$40
Name item: OrderLines!$Y$34:$Y$40
Name ItemName: OrderLines!$R$2:$R$925
Name ItemName: Menu!$B$2:$B$20
Name July: OrderLines!$K$3:$K$925
Name LastRestockDate: Inventory!$E$2:$E$20
Name LeadTimeDays: Inventory!$D$2:$D$20
Name LineNetAmount: OrderLines!$J$2:$J$925
Name MonthName: OrderLines!$K$2:$K$925
Name O00001_: OrderLines!$A$3:$A$925
Name OK: OrderLines!$O$3:$O$925
Name OnHandQty: Inventory!$B$2:$B$20
Name OrderDate: Orders!$H$2:$H$361
Name OrderDate: OrderLines!$G$2:$G$925
Name OrderDateTime: Orders!$B$2:$B$361
Name OrderID: Orders!$A$2:$A$361
Name OrderID: OrderLines!$A$2:$A$925
Name PaymentType: Orders!$E$2:$E$361
Name PaymentType: OrderLines!$M$2:$M$925
Name Poha: OrderLines!$R$3:$R$925
Name Profit: OrderLines!$Q$2:$Q$925
Name Qty: WasteLog!$C$2:$C$121
Name Qty: OrderLines!$C$2:$C$925
Name Rating: Feedback!$C$2:$C$221
Name Reason: WasteLog!$D$2:$D$121
Name region: Orders!$Q$17:$Q$21
Name ReorderPoint: Inventory!$C$2:$C$20
Name sales: Orders!$R$17:$R$21
Name Shift: Orders!$F$2:$F$361
Name Shift: OrderLines!$L$2:$L$925
Name SHJ7XV: OrderLines!$B$3:$B$925
Name Single: OrderLines!$N$3:$N$925
Name SKU: Inventory!$A$2:$A$20
Name SKU: Menu!$A$2:$A$20
Name SKU: WasteLog!$B$2:$B$121
Name SKU: OrderLines!$B$2:$B$925
Name Slicer_Branch: #N/A
Name Slicer_Branch1: #N/A
Name Slicer_Branch2: #N/A
Name Slicer_Shift: #N/A
Name Slicer_Shift1: #N/A

Sheet Orders
A1: OrderID | B1: OrderDateTime | C1: Branch | D1: CustomerType | E1: PaymentType | F1: Shift | G1: DiscountPct | H1: OrderDate | I1: Has beverage | J1: LineAmount | K1: ItemList | L1: TotalCost | M1: GrossProfit | N1: combo flag | O1: discount flag | T1: Add a combo flag( based on category) on orders
A2: O00001 | B2: 45852.096 | C2: Head Office Café | D2: Visitor | E2: UPI | F2: Breakfast | G2: 0.06 | H2: =INT($B2) -> 45852 | I2: =IF(COUNTIFS([0]!OrderID,Table3[[#This Row],[OrderID]],[0]!Category,"beverage")>0,"yes","no") -> no | J2: =SUMIFS([0]!LineNetAmount,[0]!OrderID,Table3[[#This Row],[OrderID]]) -> 147.909 | K2: {=_xlfn.TEXTJOIN("+",,_xlfn._xlws.SORT(_xlfn.UNIQUE(_xlfn._xlws.FILTER([0]!Category,[0]!OrderID=Table3[[#This Row],[OrderID]]))))} -> Snack | L2: =SUMIFS([0]!FoodCost,[0]!OrderID,Table3[[#This Row],[OrderID]]) -> 77.4 | M2: =Table3[[#This Row],[LineAmount]]-Table3[[#This Row],[TotalCost]] -> 70.509 | N2: =IF(AND(COUNTIFS([0]!OrderID,Table3[[#This Row],[OrderID]],[0]!Category,"hot meal")>0,COUNTIFS([0]!OrderID,Table3[[#This Row],[OrderID]],[0]!Category,"beverage")>0),"combo","single") -> single | O2: =IF((Table3[[#This Row],[LineAmount]]/(1-Table3[[#This Row],[DiscountPct]]))*Table3[[#This Row],[DiscountPct]]>40,"High Disc","OK") -> OK | T2: if order has >= 1 hot meal >=1 bev, return combo,ow single
A3: O00002 | B3: 45862.843 | C3: Plant 2 Canteen | D3: Staff | E3: Cash | F3: Dinner | G3: 0.05 | H3: =INT($B3) -> 45862 | I3: =IF(COUNTIFS([0]!OrderID,Table3[[#This Row],[OrderID]],[0]!Category,"beverage")>0,"yes","no") -> yes | J3: =SUMIFS([0]!LineNetAmount,[0]!OrderID,Table3[[#This Row],[OrderID]]) -> 101.5455 | K3: {=_xlfn.TEXTJOIN("+",,_xlfn._xlws.SORT(_xlfn.UNIQUE(_xlfn._xlws.FILTER([0]!Category,[0]!OrderID=Table3[[#This Row],[OrderID]]))))} -> Beverage+Dessert | L3: =SUMIFS([0]!FoodCost,[0]!OrderID,Table3[[#This Row],[OrderID]]) -> 52.41 | M3: =Table3[[#This Row],[LineAmount]]-Table3[[#This Row],[TotalCost]] -> 49.1355 | N3: =IF(AND(COUNTIFS([0]!OrderID,Table3[[#This Row],[OrderID]],[0]!Category,"hot meal")>0,COUNTIFS([0]!OrderID,Table3[[#This Row],[OrderID]],[0]!Category,"beverage")>0),"combo","single") -> single | O3: =IF((Table3[[#This Row],[LineAmount]]/(1-Table3[[#This Row],[DiscountPct]]))*Table3[[#This Row],[DiscountPct]]>40,"High Disc","OK") -> OK | Q3: day
A4: O00003 | B4: 45848.661 | C4: Head Office Café | D4: Staff | E4: Card | F4: Lunch | G4: 0 | H4: =INT($B4) -> 45848 | I4: =IF(COUNTIFS([0]!OrderID,Table3[[#This Row],[OrderID]],[0]!Category,"beverage")>0,"yes","no") -> yes | J4: =SUMIFS([0]!LineNetAmount,[0]!OrderID,Table3[[#This Row],[OrderID]]) -> 668.96 | K4: {=_xlfn.TEXTJOIN("+",,_xlfn._xlws.SORT(_xlfn.UNIQUE(_xlfn._xlws.FILTER([0]!Category,[0]!OrderID=Table3[[#This Row],[OrderID]]))))} -> Beverage+Hot Meal+Snack | L4: =SUMIFS([0]!FoodCost,[0]!OrderID,Table3[[#This Row],[OrderID]]) -> 291.24 | M4: =Table3[[#This Row],[LineAmount]]-Table3[[#This Row],[TotalCost]] -> 377.72 | N4: =IF(AND(COUNTIFS([0]!OrderID,Table3[[#This Row],[OrderID]],[0]!Category,"hot meal")>0,COUNTIFS([0]!OrderID,Table3[[#This Row],[OrderID]],[0]!Category,"beverage")>0),"combo","single") -> combo | O4: =IF((Table3[[#This Row],[LineAmount]]/(1-Table3[[#This Row],[DiscountPct]]))*Table3[[#This Row],[DiscountPct]]>40,"High Disc","OK") -> OK | Q4: 1 | R4: 1
A5: O00004 | B5: 45879.164 | C5: Plant 2 Canteen | D5: Visitor | E5: Cash | F5: Breakfast | G5: 0.03 | H5: =INT($B5) -> 45879 | I5: =IF(COUNTIFS([0]!OrderID,Table3[[#This Row],[OrderID]],[0]!Category,"beverage")>0,"yes","no") -> no | J5: =SUMIFS([0]!LineNetAmount,[0]!OrderID,Table3[[#This Row],[OrderID]]) -> 477.4146 | K5: {=_xlfn.TEXTJOIN("+",,_xlfn._xlws.SORT(_xlfn.UNIQUE(_xlfn._xlws.FILTER([0]!Category,[0]!OrderID=Table3[[#This Row],[OrderID]]))))} -> Hot Meal | L5: =SUMIFS([0]!FoodCost,[0]!OrderID,Table3[[#This Row],[OrderID]]) -> 224.16 | M5: =Table3[[#This Row],[LineAmount]]-Table3[[#This Row],[TotalCost]] -> 253.2546 | N5: =IF(AND(COUNTIFS([0]!OrderID,Table3[[#This Row],[OrderID]],[0]!Category,"hot meal")>0,COUNTIFS([0]!OrderID,Table3[[#This Row],[OrderID]],[0]!Category,"beverage")>0),"combo","single") -> single | O5: =IF((Table3[[#This Row],[LineAmount]]/(1-Table3[[#This Row],[DiscountPct]]))*Table3[[#This Row],[DiscountPct]]>40,"High Disc","OK") -> OK | Q5: 2 | R5: 0 | T5: Create a disc flag per order.
A6: O00005 | B6: 45845.135 | C6: Plant 2 Canteen | D6: Visitor | E6: Card | F6: Breakfast | G6: 0.04 | H6: =INT($B6) -> 45845 | I6: =IF(COUNTIFS([0]!OrderID,Table3[[#This Row],[OrderID]],[0]!Category,"beverage")>0,"yes","no") -> yes | J6: =SUMIFS([0]!LineNetAmount,[0]!OrderID,Table3[[#This Row],[OrderID]]) -> 95.0112 | K6: {=_xlfn.TEXTJOIN("+",,_xlfn._xlws.SORT(_xlfn.UNIQUE(_xlfn._xlws.FILTER([0]!Category,[0]!OrderID=Table3[[#This Row],[OrderID]]))))} -> Beverage+Snack | L6: =SUMIFS([0]!FoodCost,[0]!OrderID,Table3[[#This Row],[OrderID]]) -> 49.7 | M6: =Table3[[#This Row],[LineAmount]]-Table3[[#This Row],[TotalCost]] -> 45.3112 | N6: =IF(AND(COUNTIFS([0]!OrderID,Table3[[#This Row],[OrderID]],[0]!Category,"hot meal")>0,COUNTIFS([0]!OrderID,Table3[[#This Row],[OrderID]],[0]!Category,"beverage")>0),"combo","single") -> single | O6: =IF((Table3[[#This Row],[LineAmount]]/(1-Table3[[#This Row],[DiscountPct]]))*Table3[[#This Row],[DiscountPct]]>40,"High Disc","OK") -> OK | Q6: 3 | R6: 1 | T6: if total order discount value > 40, "highdisc","ok"
A7: O00006 | B7: 45863.392 | C7: Plant 1 Canteen | D7: Worker | E7: UPI | F7: Breakfast | G7: 0.1 | H7: =INT($B7) -> 45863 | I7: =IF(COUNTIFS([0]!OrderID,Table3[[#This Row],[OrderID]],[0]!Category,"beverage")>0,"yes","no") -> yes | J7: =SUMIFS([0]!LineNetAmount,[0]!OrderID,Table3[[#This Row],[OrderID]]) -> 54.297 | K7: {=_xlfn.TEXTJOIN("+",,_xlfn._xlws.SORT(_xlfn.UNIQUE(_xlfn._xlws.FILTER([0]!Category,[0]!OrderID=Table3[[#This Row],[OrderID]]))))} -> Beverage | L7: =SUMIFS([0]!FoodCost,[0]!OrderID,Table3[[#This Row],[OrderID]]) -> 24 | M7: =Table3[[#This Row],[LineAmount]]-Table3[[#This Row],[TotalCost]] -> 30.297 | N7: =IF(AND(COUNTIFS([0]!OrderID,Table3[[#This Row],[OrderID]],[0]!Category,"hot meal")>0,COUNTIFS([0]!OrderID,Table3[[#This Row],[OrderID]],[0]!Category,"beverage")>0),"combo","single") -> single | O7: =IF((Table3[[#This Row],[LineAmount]]/(1-Table3[[#This Row],[DiscountPct]]))*Table3[[#This Row],[DiscountPct]]>40,"High Disc","OK") -> OK | Q7: 4 | R7: 1
A8: O00007 | B8: 45852.86 | C8: Plant 2 Canteen | D8: Worker | E8: Card | F8: Dinner | G8: 0.07 | H8: =INT($B8) -> 45852 | I8: =IF(COUNTIFS([0]!OrderID,Table3[[#This Row],[OrderID]],[0]!Category,"beverage")>0,"yes","no") -> yes | J8: =SUMIFS([0]!LineNetAmount,[0]!OrderID,Table3[[#This Row],[OrderID]]) -> 348.4152 | K8: {=_xlfn.TEXTJOIN("+",,_xlfn._xlws.SORT(_xlfn.UNIQUE(_xlfn._xlws.FILTER([0]!Category,[0]!OrderID=Table3[[#This Row],[OrderID]]))))} -> Beverage+Hot Meal | L8: =SUMIFS([0]!FoodCost,[0]!OrderID,Table3[[#This Row],[OrderID]]) -> 159.98 | M8: =Table3[[#This Row],[LineAmount]]-Table3[[#This Row],[TotalCost]] -> 188.4352 | N8: =IF(AND(COUNTIFS([0]!OrderID,Table3[[#This Row],[OrderID]],[0]!Category,"hot meal")>0,COUNTIFS([0]!OrderID,Table3[[#This Row],[OrderID]],[0]!Category,"beverage")>0),"combo","single") -> combo | O8: =IF((Table3[[#This Row],[LineAmount]]/(1-Table3[[#This Row],[DiscountPct]]))*Table3[[#This Row],[DiscountPct]]>40,"High Disc","OK") -> OK | Q8: 5 | R8: 1
A9: O00008 | B9: 45863.504 | C9: Plant 1 Canteen | D9: Staff | E9: UPI | F9: Lunch | G9: 0 | H9: =INT($B9) -> 45863 | I9: =IF(COUNTIFS([0]!OrderID,Table3[[#This Row],[OrderID]],[0]!Category,"beverage")>0,"yes","no") -> yes | J9: =SUMIFS([0]!LineNetAmount,[0]!OrderID,Table3[[#This Row],[OrderID]]) -> 223.75 | K9: {=_xlfn.TEXTJOIN("+",,_xlfn._xlws.SORT(_xlfn.UNIQUE(_xlfn._xlws.FILTER([0]!Category,[0]!OrderID=Table3[[#This Row],[OrderID]]))))} -> Beverage+Dessert | L9: =SUMIFS([0]!FoodCost,[0]!OrderID,Table3[[#This Row],[OrderID]]) -> 110.98 | M9: =Table3[[#This Row],[LineAmount]]-Table3[[#This Row],[TotalCost]] -> 112.77 | N9: =IF(AND(COUNTIFS([0]!OrderID,Table3[[#This Row],[OrderID]],[0]!Category,"hot meal")>0,COUNTIFS([0]!OrderID,Table3[[#This Row],[OrderID]],[0]!Category,"beverage")>0),"combo","single") -> single | O9: =IF((Table3[[#This Row],[LineAmount]]/(1-Table3[[#This Row],[DiscountPct]]))*Table3[[#This Row],[DiscountPct]]>40,"High Disc","OK") -> OK | Q9: 6 | R9: 1
A10: O00009 | B10: 45844.162 | C10: Head Office Café | D10: Visitor | E10: Cash | F10: Breakfast | G10: 0.07 | H10: =INT($B10) -> 45844 | I10: =IF(COUNTIFS([0]!OrderID,Table3[[#This Row],[OrderID]],[0]!Category,"beverage")>0,"yes","no") -> no | J10: =SUMIFS([0]!LineNetAmount,[0]!OrderID,Table3[[#This Row],[OrderID]]) -> 459.2898 | K10: {=_xlfn.TEXTJOIN("+",,_xlfn._xlws.SORT(_xlfn.UNIQUE(_xlfn._xlws.FILTER([0]!Category,[0]!OrderID=Table3[[#This Row],[OrderID]]))))} -> Dessert+Hot Meal+Snack | L10: =SUMIFS([0]!FoodCost,[0]!OrderID,Table3[[#This Row],[OrderID]]) -> 225.97 | M10: =Table3[[#This Row],[LineAmount]]-Table3[[#This Row],[TotalCost]] -> 233.3198 | N10: =IF(AND(COUNTIFS([0]!OrderID,Table3[[#This Row],[OrderID]],[0]!Category,"hot meal")>0,COUNTIFS([0]!OrderID,Table3[[#This Row],[OrderID]],[0]!Category,"beverage")>0),"combo","single") -> single | O10: =IF((Table3[[#This Row],[LineAmount]]/(1-Table3[[#This Row],[DiscountPct]]))*Table3[[#This Row],[DiscountPct]]>40,"High Disc","OK") -> OK | Q10: 7 | R10: 0
A11: O00010 | B11: 45862.2 | C11: Plant 1 Canteen | D11: Staff | E11: Card | F11: Breakfast | G11: 0.04 | H11: =INT($B11) -> 45862 | I11: =IF(COUNTIFS([0]!OrderID,Table3[[#This Row],[OrderID]],[0]!Category,"beverage")>0,"yes","no") -> yes | J11: =SUMIFS([0]!LineNetAmount,[0]!OrderID,Table3[[#This Row],[OrderID]]) -> 420.0768 | K11: {=_xlfn.TEXTJOIN("+",,_xlfn._xlws.SORT(_xlfn.UNIQUE(_xlfn._xlws.FILTER([0]!Category,[0]!OrderID=Table3[[#This Row],[OrderID]]))))} -> Beverage+Dessert+Hot Meal+Snack | L11: =SUMIFS([0]!FoodCost,[0]!OrderID,Table3[[#This Row],[OrderID]]) -> 204.88 | M11: =Table3[[#This Row],[LineAmount]]-Table3[[#This Row],[TotalCost]] -> 215.1968 | N11: =IF(AND(COUNTIFS([0]!OrderID,Table3[[#This Row],[OrderID]],[0]!Category,"hot meal")>0,COUNTIFS([0]!OrderID,Table3[[#This Row],[OrderID]],[0]!Category,"beverage")>0),"combo","single") -> combo | O11: =IF((Table3[[#This Row],[LineAmount]]/(1-Table3[[#This Row],[DiscountPct]]))*Table3[[#This Row],[DiscountPct]]>40,"High Disc","OK") -> OK | T11: if total order discount value = pre disc total* disc pct
A12: O00011 | B12: 45860.003 | C12: Plant 2 Canteen | D12: Worker | E12: Cash | F12: Breakfast | G12: 0.03 | H12: =INT($B12) -> 45860 | I12: =IF(COUNTIFS([0]!OrderID,Table3[[#This Row],[OrderID]],[0]!Category,"beverage")>0,"yes","no") -> yes | J12: =SUMIFS([0]!LineNetAmount,[0]!OrderID,Table3[[#This Row],[OrderID]]) -> 27.5771 | K12: {=_xlfn.TEXTJOIN("+",,_xlfn._xlws.SORT(_xlfn.UNIQUE(_xlfn._xlws.FILTER([0]!Category,[0]!OrderID=Table3[[#This Row],[OrderID]]))))} -> Beverage | L12: =SUMIFS([0]!FoodCost,[0]!OrderID,Table3[[#This Row],[OrderID]]) -> 13.89 | M12: =Table3[[#This Row],[LineAmount]]-Table3[[#This Row],[TotalCost]] -> 13.6871 | N12: =IF(AND(COUNTIFS([0]!OrderID,Table3[[#This Row],[OrderID]],[0]!Category,"hot meal")>0,COUNTIFS([0]!OrderID,Table3[[#This Row],[OrderID]],[0]!Category,"beverage")>0),"combo","single") -> single | O12: =IF((Table3[[#This Row],[LineAmount]]/(1-Table3[[#This Row],[DiscountPct]]))*Table3[[#This Row],[DiscountPct]]>40,"High Disc","OK") -> OK | W12: (p*q)*disc pct
A13: O00012 | B13: 45839.459 | C13: Plant 2 Canteen | D13: Staff | E13: Card | F13: Lunch | G13: 0.08 | H13: =INT($B13) -> 45839 | I13: =IF(COUNTIFS([0]!OrderID,Table3[[#This Row],[OrderID]],[0]!Category,"beverage")>0,"yes","no") -> no | J13: =SUMIFS([0]!LineNetAmount,[0]!OrderID,Table3[[#This Row],[OrderID]]) -> 98.118 | K13: {=_xlfn.TEXTJOIN("+",,_xlfn._xlws.SORT(_xlfn.UNIQUE(_xlfn._xlws.FILTER([0]!Category,[0]!OrderID=Table3[[#This Row],[OrderID]]))))} -> Dessert+Snack | L13: =SUMIFS([0]!FoodCost,[0]!OrderID,Table3[[#This Row],[OrderID]]) -> 47.75 | M13: =Table3[[#This Row],[LineAmount]]-Table3[[#This Row],[TotalCost]] -> 50.368 | N13: =IF(AND(COUNTIFS([0]!OrderID,Table3[[#This Row],[OrderID]],[0]!Category,"hot meal")>0,COUNTIFS([0]!OrderID,Table3[[#This Row],[OrderID]],[0]!Category,"beverage")>0),"combo","single") -> single | O13: =IF((Table3[[#This Row],[LineAmount]]/(1-Table3[[#This Row],[DiscountPct]]))*Table3[[#This Row],[DiscountPct]]>40,"High Disc","OK") -> OK
A14: O00013 | B14: 45880.32 | C14: Head Office Café | D14: Visitor | E14: UPI | F14: Breakfast | G14: 0.1 | H14: =INT($B14) -> 45880 | I14: =IF(COUNTIFS([0]!OrderID,Table3[[#This Row],[OrderID]],[0]!Category,"beverage")>0,"yes","no") -> yes | J14: =SUMIFS([0]!LineNetAmount,[0]!OrderID,Table3[[#This Row],[OrderID]]) -> 807.876 | K14: {=_xlfn.TEXTJOIN("+",,_xlfn._xlws.SORT(_xlfn.UNIQUE(_xlfn._xlws.FILTER([0]!Category,[0]!OrderID=Table3[[#This Row],[OrderID]]))))} -> Beverage+Dessert+Hot Meal | L14: =SUMIFS([0]!FoodCost,[0]!OrderID,Table3[[#This Row],[OrderID]]) -> 411.2 | M14: =Table3[[#This Row],[LineAmount]]-Table3[[#This Row],[TotalCost]] -> 396.676 | N14: =IF(AND(COUNTIFS([0]!OrderID,Table3[[#This Row],[OrderID]],[0]!Category,"hot meal")>0,COUNTIFS([0]!OrderID,Table3[[#This Row],[OrderID]],[0]!Category,"beverage")>0),"combo","single") -> combo | O14: =IF((Table3[[#This Row],[LineAmount]]/(1-Table3[[#This Row],[DiscountPct]]))*Table3[[#This Row],[DiscountPct]]>40,"High Disc","OK") -> High Disc
A15: O00014 | B15: 45854.279 | C15: Plant 1 Canteen | D15: Staff | E15: Cash | F15: Breakfast | G15: 0.1 | H15: =INT($B15) -> 45854 | I15: =IF(COUNTIFS([0]!OrderID,Table3[[#This Row],[OrderID]],[0]!Category,"beverage")>0,"yes","no") -> yes | J15: =SUMIFS([0]!LineNetAmount,[0]!OrderID,Table3[[#This Row],[OrderID]]) -> 181.476 | K15: {=_xlfn.TEXTJOIN("+",,_xlfn._xlws.SORT(_xlfn.UNIQUE(_xlfn._xlws.FILTER([0]!Category,[0]!OrderID=Table3[[#This Row],[OrderID]]))))} -> Beverage+Dessert | L15: =SUMIFS([0]!FoodCost,[0]!OrderID,Table3[[#This Row],[OrderID]]) -> 98.35 | M15: =Table3[[#This Row],[LineAmount]]-Table3[[#This Row],[TotalCost]] -> 83.126 | N15: =IF(AND(COUNTIFS([0]!OrderID,Table3[[#This Row],[OrderID]],[0]!Category,"hot meal")>0,COUNTIFS([0]!OrderID,Table3[[#This Row],[OrderID]],[0]!Category,"beverage")>0),"combo","single") -> single | O15: =IF((Table3[[#This Row],[LineAmount]]/(1-Table3[[#This Row],[DiscountPct]]))*Table3[[#This Row],[DiscountPct]]>40,"High Disc","OK") -> OK
A16: O00015 | B16: 45895.483 | C16: Head Office Café | D16: Visitor | E16: Cash | F16: Lunch | G16: 0.03 | H16: =INT($B16) -> 45895 | I16: =IF(COUNTIFS([0]!OrderID,Table3[[#This Row],[OrderID]],[0]!Category,"beverage")>0,"yes","no") -> yes | J16: =SUMIFS([0]!LineNetAmount,[0]!OrderID,Table3[[#This Row],[OrderID]]) -> 410.1839 | K16: {=_xlfn.TEXTJOIN("+",,_xlfn._xlws.SORT(_xlfn.UNIQUE(_xlfn._xlws.FILTER([0]!Category,[0]!OrderID=Table3[[#This Row],[OrderID]]))))} -> Beverage+Dessert+Hot Meal | L16: =SUMIFS([0]!FoodCost,[0]!OrderID,Table3[[#This Row],[OrderID]]) -> 186.05 | M16: =Table3[[#This Row],[LineAmount]]-Table3[[#This Row],[TotalCost]] -> 224.1339 | N16: =IF(AND(COUNTIFS([0]!OrderID,Table3[[#This Row],[OrderID]],[0]!Category,"hot meal")>0,COUNTIFS([0]!OrderID,Table3[[#This Row],[OrderID]],[0]!Category,"beverage")>0),"combo","single") -> combo | O16: =IF((Table3[[#This Row],[LineAmount]]/(1-Table3[[#This Row],[DiscountPct]]))*Table3[[#This Row],[DiscountPct]]>40,"High Disc","OK") -> OK
A17: O00016 | B17: 45844.8 | C17: Plant 1 Canteen | D17: Visitor | E17: Card | F17: Dinner | G17: 0.05 | H17: =INT($B17) -> 45844 | I17: =IF(COUNTIFS([0]!OrderID,Table3[[#This Row],[OrderID]],[0]!Category,"beverage")>0,"yes","no") -> no | J17: =SUMIFS([0]!LineNetAmount,[0]!OrderID,Table3[[#This Row],[OrderID]]) -> 486.9415 | K17: {=_xlfn.TEXTJOIN("+",,_xlfn._xlws.SORT(_xlfn.UNIQUE(_xlfn._xlws.FILTER([0]!Category,[0]!OrderID=Table3[[#This Row],[OrderID]]))))} -> Dessert+Hot Meal+Snack | L17: =SUMIFS([0]!FoodCost,[0]!OrderID,Table3[[#This Row],[OrderID]]) -> 238.57 | M17: =Table3[[#This Row],[LineAmount]]-Table3[[#This Row],[TotalCost]] -> 248.3715 | N17: =IF(AND(COUNTIFS([0]!OrderID,Table3[[#This Row],[OrderID]],[0]!Category,"hot meal")>0,COUNTIFS([0]!OrderID,Table3[[#This Row],[OrderID]],[0]!Category,"beverage")>0),"combo","single") -> single | O17: =IF((Table3[[#This Row],[LineAmount]]/(1-Table3[[#This Row],[DiscountPct]]))*Table3[[#This Row],[DiscountPct]]>40,"High Disc","OK") -> OK
A18: O00017 | B18: 45890.817 | C18: Plant 1 Canteen | D18: Worker | E18: UPI | F18: Dinner | G18: 0.07 | H18: =INT($B18) -> 45890 | I18: =IF(COUNTIFS([0]!OrderID,Table3[[#This Row],[OrderID]],[0]!Category,"beverage")>0,"yes","no") -> yes | J18: =SUMIFS([0]!LineNetAmount,[0]!OrderID,Table3[[#This Row],[OrderID]]) -> 30.6714 | K18: {=_xlfn.TEXTJOIN("+",,_xlfn._xlws.SORT(_xlfn.UNIQUE(_xlfn._xlws.FILTER([0]!Category,[0]!OrderID=Table3[[#This Row],[OrderID]]))))} -> Beverage | L18: =SUMIFS([0]!FoodCost,[0]!OrderID,Table3[[#This Row],[OrderID]]) -> 11.84 | M18: =Table3[[#This Row],[LineAmount]]-Table3[[#This Row],[TotalCost]] -> 18.8314 | N18: =IF(AND(COUNTIFS([0]!OrderID,Table3[[#This Row],[OrderID]],[0]!Category,"hot meal")>0,COUNTIFS([0]!OrderID,Table3[[#This Row],[OrderID]],[0]!Category,"beverage")>0),"combo","single") -> single | O18: =IF((Table3[[#This Row],[LineAmount]]/(1-Table3[[#This Row],[DiscountPct]]))*Table3[[#This Row],[DiscountPct]]>40,"High Disc","OK") -> OK | R18: 450 | S18: 1000g | V18: 32 | W18: 1000
A19: O00018 | B19: 45857.292 | C19: Plant 1 Canteen | D19: Visitor | E19: Cash | F19: Breakfast | G19: 0.1 | H19: =INT($B19) -> 45857 | I19: =IF(COUNTIFS([0]!OrderID,Table3[[#This Row],[OrderID]],[0]!Category,"beverage")>0,"yes","no") -> yes | J19: =SUMIFS([0]!LineNetAmount,[0]!OrderID,Table3[[#This Row],[OrderID]]) -> 164.484 | K19: {=_xlfn.TEXTJOIN("+",,_xlfn._xlws.SORT(_xlfn.UNIQUE(_xlfn._xlws.FILTER([0]!Category,[0]!OrderID=Table3[[#This Row],[OrderID]]))))} -> Beverage+Dessert | L19: =SUMIFS([0]!FoodCost,[0]!OrderID,Table3[[#This Row],[OrderID]]) -> 72.65 | M19: =Table3[[#This Row],[LineAmount]]-Table3[[#This Row],[TotalCost]] -> 91.834 | N19: =IF(AND(COUNTIFS([0]!OrderID,Table3[[#This Row],[OrderID]],[0]!Category,"hot meal")>0,COUNTIFS([0]!OrderID,Table3[[#This Row],[OrderID]],[0]!Category,"beverage")>0),"combo","single") -> single | O19: =IF((Table3[[#This Row],[LineAmount]]/(1-Table3[[#This Row],[DiscountPct]]))*Table3[[#This Row],[DiscountPct]]>40,"High Disc","OK") -> OK | R19: ? | S19: 350g | V19: ? | W19: 120
A20: O00019 | B20: 45878.453 | C20: Plant 1 Canteen | D20: Visitor | E20: Cash | F20: Breakfast | G20: 0.04 | H20: =INT($B20) -> 45878 | I20: =IF(COUNTIFS([0]!OrderID,Table3[[#This Row],[OrderID]],[0]!Category,"beverage")>0,"yes","no") -> no | J20: =SUMIFS([0]!LineNetAmount,[0]!OrderID,Table3[[#This Row],[OrderID]]) -> 701.5296 | K20: {=_xlfn.TEXTJOIN("+",,_xlfn._xlws.SORT(_xlfn.UNIQUE(_xlfn._xlws.FILTER([0]!Category,[0]!OrderID=Table3[[#This Row],[OrderID]]))))} -> Hot Meal+Snack | L20: =SUMIFS([0]!FoodCost,[0]!OrderID,Table3[[#This Row],[OrderID]]) -> 359.21 | M20: =Table3[[#This Row],[LineAmount]]-Table3[[#This Row],[TotalCost]] -> 342.3196 | N20: =IF(AND(COUNTIFS([0]!OrderID,Table3[[#This Row],[OrderID]],[0]!Category,"hot meal")>0,COUNTIFS([0]!OrderID,Table3[[#This Row],[OrderID]],[0]!Category,"beverage")>0),"combo","single") -> single | O20: =IF((Table3[[#This Row],[LineAmount]]/(1-Table3[[#This Row],[DiscountPct]]))*Table3[[#This Row],[DiscountPct]]>40,"High Disc","OK") -> OK
A21: O00020 | B21: 45847.21 | C21: Plant 2 Canteen | D21: Visitor | E21: UPI | F21: Breakfast | G21: 0.05 | H21: =INT($B21) -> 45847 | I21: =IF(COUNTIFS([0]!OrderID,Table3[[#This Row],[OrderID]],[0]!Category,"beverage")>0,"yes","no") -> yes | J21: =SUMIFS([0]!LineNetAmount,[0]!OrderID,Table3[[#This Row],[OrderID]]) -> 474.753 | K21: {=_xlfn.TEXTJOIN("+",,_xlfn._xlws.SORT(_xlfn.UNIQUE(_xlfn._xlws.FILTER([0]!Category,[0]!OrderID=Table3[[#This Row],[OrderID]]))))} -> Beverage+Dessert+Hot Meal | L21: =SUMIFS([0]!FoodCost,[0]!OrderID,Table3[[#This Row],[OrderID]]) -> 212.14 | M21: =Table3[[#This Row],[LineAmount]]-Table3[[#This Row],[TotalCost]] -> 262.613 | N21: =IF(AND(COUNTIFS([0]!OrderID,Table3[[#This Row],[OrderID]],[0]!Category,"hot meal")>0,COUNTIFS([0]!OrderID,Table3[[#This Row],[OrderID]],[0]!Category,"beverage")>0),"combo","single") -> combo | O21: =IF((Table3[[#This Row],[LineAmount]]/(1-Table3[[#This Row],[DiscountPct]]))*Table3[[#This Row],[DiscountPct]]>40,"High Disc","OK") -> OK
A22: O00021 | B22: 45869.966 | C22: Plant 2 Canteen | D22: Worker | E22: UPI | F22: Dinner | G22: 0.02 | H22: =INT($B22) -> 45869 | I22: =IF(COUNTIFS([0]!OrderID,Table3[[#This Row],[OrderID]],[0]!Category,"beverage")>0,"yes","no") -> no | J22: =SUMIFS([0]!LineNetAmount,[0]!OrderID,Table3[[#This Row],[OrderID]]) -> 291.7264 | K22: {=_xlfn.TEXTJOIN("+",,_xlfn._xlws.SORT(_xlfn.UNIQUE(_xlfn._xlws.FILTER([0]!Category,[0]!OrderID=Table3[[#This Row],[OrderID]]))))} -> Snack | L22: =SUMIFS([0]!FoodCost,[0]!OrderID,Table3[[#This Row],[OrderID]]) -> 138.13 | M22: =Table3[[#This Row],[LineAmount]]-Table3[[#This Row],[TotalCost]] -> 153.5964 | N22: =IF(AND(COUNTIFS([0]!OrderID,Table3[[#This Row],[OrderID]],[0]!Category,"hot meal")>0,COUNTIFS([0]!OrderID,Table3[[#This Row],[OrderID]],[0]!Category,"beverage")>0),"combo","single") -> single | O22: =IF((Table3[[#This Row],[LineAmount]]/(1-Table3[[#This Row],[DiscountPct]]))*Table3[[#This Row],[DiscountPct]]>40,"High Disc","OK") -> OK | R22: =450/2 -> 225
A23: O00022 | B23: 45862.424 | C23: Plant 2 Canteen | D23: Staff | E23: Cash | F23: Breakfast | G23: 0.01 | H23: =INT($B23) -> 45862 | I23: =IF(COUNTIFS([0]!OrderID,Table3[[#This Row],[OrderID]],[0]!Category,"beverage")>0,"yes","no") -> yes | J23: =SUMIFS([0]!LineNetAmount,[0]!OrderID,Table3[[#This Row],[OrderID]]) -> 364.2903 | K23: {=_xlfn.TEXTJOIN("+",,_xlfn._xlws.SORT(_xlfn.UNIQUE(_xlfn._xlws.FILTER([0]!Category,[0]!OrderID=Table3[[#This Row],[OrderID]]))))} -> Beverage+Dessert+Hot Meal | L23: =SUMIFS([0]!FoodCost,[0]!OrderID,Table3[[#This Row],[OrderID]]) -> 170.97 | M23: =Table3[[#This Row],[LineAmount]]-Table3[[#This Row],[TotalCost]] -> 193.3203 | N23: =IF(AND(COUNTIFS([0]!OrderID,Table3[[#This Row],[OrderID]],[0]!Category,"hot meal")>0,COUNTIFS([0]!OrderID,Table3[[#This Row],[OrderID]],[0]!Category,"beverage")>0),"combo","single") -> combo | O23: =IF((Table3[[#This Row],[LineAmount]]/(1-Table3[[#This Row],[DiscountPct]]))*Table3[[#This Row],[DiscountPct]]>40,"High Disc","OK") -> OK
A24: O00023 | B24: 45883.642 | C24: Plant 2 Canteen | D24: Worker | E24: Cash | F24: Lunch | G24: 0.09 | H24: =INT($B24) -> 45883 | I24: =IF(COUNTIFS([0]!OrderID,Table3[[#This Row],[OrderID]],[0]!Category,"beverage")>0,"yes","no") -> yes | J24: =SUMIFS([0]!LineNetAmount,[0]!OrderID,Table3[[#This Row],[OrderID]]) -> 242.242 | K24: {=_xlfn.TEXTJOIN("+",,_xlfn._xlws.SORT(_xlfn.UNIQUE(_xlfn._xlws.FILTER([0]!Category,[0]!OrderID=Table3[[#This Row],[OrderID]]))))} -> Beverage+Hot Meal | L24: =SUMIFS([0]!FoodCost,[0]!OrderID,Table3[[#This Row],[OrderID]]) -> 120.08 | M24: =Table3[[#This Row],[LineAmount]]-Table3[[#This Row],[TotalCost]] -> 122.162 | N24: =IF(AND(COUNTIFS([0]!OrderID,Table3[[#This Row],[OrderID]],[0]!Category,"hot meal")>0,COUNTIFS([0]!OrderID,Table3[[#This Row],[OrderID]],[0]!Category,"beverage")>0),"combo","single") -> combo | O24: =IF((Table3[[#This Row],[LineAmount]]/(1-Table3[[#This Row],[DiscountPct]]))*Table3[[#This Row],[DiscountPct]]>40,"High Disc","OK") -> OK
A25: O00024 | B25: 45893.911 | C25: Plant 1 Canteen | D25: Worker | E25: UPI | F25: Dinner | G25: 0.11 | H25: =INT($B25) -> 45893 | I25: =IF(COUNTIFS([0]!OrderID,Table3[[#This Row],[OrderID]],[0]!Category,"beverage")>0,"yes","no") -> no | J25: =SUMIFS([0]!LineNetAmount,[0]!OrderID,Table3[[#This Row],[OrderID]]) -> 390.888 | K25: {=_xlfn.TEXTJOIN("+",,_xlfn._xlws.SORT(_xlfn.UNIQUE(_xlfn._xlws.FILTER([0]!Category,[0]!OrderID=Table3[[#This Row],[OrderID]]))))} -> Hot Meal | L25: =SUMIFS([0]!FoodCost,[0]!OrderID,Table3[[#This Row],[OrderID]]) -> 242.76 | M25: =Table3[[#This Row],[LineAmount]]-Table3[[#This Row],[TotalCost]] -> 148.128 | N25: =IF(AND(COUNTIFS([0]!OrderID,Table3[[#This Row],[OrderID]],[0]!Category,"hot meal")>0,COUNTIFS([0]!OrderID,Table3[[#This Row],[OrderID]],[0]!Category,"beverage")>0),"combo","single") -> single | O25: =IF((Table3[[#This Row],[LineAmount]]/(1-Table3[[#This Row],[DiscountPct]]))*Table3[[#This Row],[DiscountPct]]>40,"High Disc","OK") -> High Disc
A26: O00025 | B26: 45888.367 | C26: Plant 2 Canteen | D26: Worker | E26: Card | F26: Breakfast | G26: 0.06 | H26: =INT($B26) -> 45888 | I26: =IF(COUNTIFS([0]!OrderID,Table3[[#This Row],[OrderID]],[0]!Category,"beverage")>0,"yes","no") -> no | J26: =SUMIFS([0]!LineNetAmount,[0]!OrderID,Table3[[#This Row],[OrderID]]) -> 47.1786 | K26: {=_xlfn.TEXTJOIN("+",,_xlfn._xlws.SORT(_xlfn.UNIQUE(_xlfn._xlws.FILTER([0]!Category,[0]!OrderID=Table3[[#This Row],[OrderID]]))))} -> Snack | L26: =SUMIFS([0]!FoodCost,[0]!OrderID,Table3[[#This Row],[OrderID]]) -> 22.61 | M26: =Table3[[#This Row],[LineAmount]]-Table3[[#This Row],[TotalCost]] -> 24.5686 | N26: =IF(AND(COUNTIFS([0]!OrderID,Table3[[#This Row],[OrderID]],[0]!Category,"hot meal")>0,COUNTIFS([0]!OrderID,Table3[[#This Row],[OrderID]],[0]!Category,"beverage")>0),"combo","single") -> single | O26: =IF((Table3[[#This Row],[LineAmount]]/(1-Table3[[#This Row],[DiscountPct]]))*Table3[[#This Row],[DiscountPct]]>40,"High Disc","OK") -> OK
A27: O00026 | B27: 45862.968 | C27: Plant 2 Canteen | D27: Staff | E27: Cash | F27: Dinner | G27: 0.1 | H27: =INT($B27) -> 45862 | I27: =IF(COUNTIFS([0]!OrderID,Table3[[#This Row],[OrderID]],[0]!Category,"beverage")>0,"yes","no") -> no | J27: =SUMIFS([0]!LineNetAmount,[0]!OrderID,Table3[[#This Row],[OrderID]]) -> 81.459 | K27: {=_xlfn.TEXTJOIN("+",,_xlfn._xlws.SORT(_xlfn.UNIQUE(_xlfn._xlws.FILTER([0]!Category,[0]!OrderID=Table3[[#This Row],[OrderID]]))))} -> Snack | L27: =SUMIFS([0]!FoodCost,[0]!OrderID,Table3[[#This Row],[OrderID]]) -> 45.35 | M27: =Table3[[#This Row],[LineAmount]]-Table3[[#This Row],[TotalCost]] -> 36.109 | N27: =IF(AND(COUNTIFS([0]!OrderID,Table3[[#This Row],[OrderID]],[0]!Category,"hot meal")>0,COUNTIFS([0]!OrderID,Table3[[#This Row],[OrderID]],[0]!Category,"beverage")>0),"combo","single") -> single | O27: =IF((Table3[[#This Row],[LineAmount]]/(1-Table3[[#This Row],[DiscountPct]]))*Table3[[#This Row],[DiscountPct]]>40,"High Disc","OK") -> OK
A28: O00027 | B28: 45891.991 | C28: Head Office Café | D28: Staff | E28: UPI | F28: Dinner | G28: 0.07 | H28: =INT($B28) -> 45891 | I28: =IF(COUNTIFS([0]!OrderID,Table3[[#This Row],[OrderID]],[0]!Category,"beverage")>0,"yes","no") -> yes | J28: =SUMIFS([0]!LineNetAmount,[0]!OrderID,Table3[[#This Row],[OrderID]]) -> 839.8458 | K28: {=_xlfn.TEXTJOIN("+",,_xlfn._xlws.SORT(_xlfn.UNIQUE(_xlfn._xlws.FILTER([0]!Category,[0]!OrderID=Table3[[#This Row],[OrderID]]))))} -> Beverage+Dessert+Hot Meal | L28: =SUMIFS([0]!FoodCost,[0]!OrderID,Table3[[#This Row],[OrderID]]) -> 406.75 | M28: =Table3[[#This Row],[LineAmount]]-Table3[[#This Row],[TotalCost]] -> 433.0958 | N28: =IF(AND(COUNTIFS([0]!OrderID,Table3[[#This Row],[OrderID]],[0]!Category,"hot meal")>0,COUNTIFS([0]!OrderID,Table3[[#This Row],[OrderID]],[0]!Category,"beverage")>0),"combo","single") -> combo | O28: =IF((Table3[[#This Row],[LineAmount]]/(1-Table3[[#This Row],[DiscountPct]]))*Table3[[#This Row],[DiscountPct]]>40,"High Disc","OK") -> High Disc
A29: O00028 | B29: 45840.01 | C29: Head Office Café | D29: Visitor | E29: Card | F29: Breakfast | G29: 0.03 | H29: =INT($B29) -> 45840 | I29: =IF(COUNTIFS([0]!OrderID,Table3[[#This Row],[OrderID]],[0]!Category,"beverage")>0,"yes","no") -> yes | J29: =SUMIFS([0]!LineNetAmount,[0]!OrderID,Table3[[#This Row],[OrderID]]) -> 382.7135 | K29: {=_xlfn.TEXTJOIN("+",,_xlfn._xlws.SORT(_xlfn.UNIQUE(_xlfn._xlws.FILTER([0]!Category,[0]!OrderID=Table3[[#This Row],[OrderID]]))))} -> Beverage+Dessert+Snack | L29: =SUMIFS([0]!FoodCost,[0]!OrderID,Table3[[#This Row],[OrderID]]) -> 172.36 | M29: =Table3[[#This Row],[LineAmount]]-Table3[[#This Row],[TotalCost]] -> 210.3535 | N29: =IF(AND(COUNTIFS([0]!OrderID,Table3[[#This Row],[OrderID]],[0]!Category,"hot meal")>0,COUNTIFS([0]!OrderID,Table3[[#This Row],[OrderID]],[0]!Category,"beverage")>0),"combo","single") -> single | O29: =IF((Table3[[#This Row],[LineAmount]]/(1-Table3[[#This Row],[DiscountPct]]))*Table3[[#This Row],[DiscountPct]]>40,"High Disc","OK") -> OK
A30: O00029 | B30: 45852.288 | C30: Plant 2 Canteen | D30: Worker | E30: Cash | F30: Breakfast | G30: 0.07 | H30: =INT($B30) -> 45852 | I30: =IF(COUNTIFS([0]!OrderID,Table3[[#This Row],[OrderID]],[0]!Category,"beverage")>0,"yes","no") -> no | J30: =SUMIFS([0]!LineNetAmount,[0]!OrderID,Table3[[#This Row],[OrderID]]) -> 140.0301 | K30: {=_xlfn.TEXTJOIN("+",,_xlfn._xlws.SORT(_xlfn.UNIQUE(_xlfn._xlws.FILTER([0]!Category,[0]!OrderID=Table3[[#This Row],[OrderID]]))))} -> Snack | L30: =SUMIFS([0]!FoodCost,[0]!OrderID,Table3[[#This Row],[OrderID]]) -> 67.83 | M30: =Table3[[#This Row],[LineAmount]]-Table3[[#This Row],[TotalCost]] -> 72.2001 | N30: =IF(AND(COUNTIFS([0]!OrderID,Table3[[#This Row],[OrderID]],[0]!Category,"hot meal")>0,COUNTIFS([0]!OrderID,Table3[[#This Row],[OrderID]],[0]!Category,"beverage")>0),"combo","single") -> single | O30: =IF((Table3[[#This Row],[LineAmount]]/(1-Table3[[#This Row],[DiscountPct]]))*Table3[[#This Row],[DiscountPct]]>40,"High Disc","OK") -> OK
A31: O00030 | B31: 45854.342 | C31: Plant 2 Canteen | D31: Staff | E31: UPI | F31: Breakfast | G31: 0.12 | H31: =INT($B31) -> 45854 | I31: =IF(COUNTIFS([0]!OrderID,Table3[[#This Row],[OrderID]],[0]!Category,"beverage")>0,"yes","no") -> yes | J31: =SUMIFS([0]!LineNetAmount,[0]!OrderID,Table3[[#This Row],[OrderID]]) -> 365.728 | K31: {=_xlfn.TEXTJOIN("+",,_xlfn._xlws.SORT(_xlfn.UNIQUE(_xlfn._xlws.FILTER([0]!Category,[0]!OrderID=Table3[[#This Row],[OrderID]]))))} -> Beverage+Hot Meal+Snack | L31: =SUMIFS([0]!FoodCost,[0]!OrderID,Table3[[#This Row],[OrderID]]) -> 197.59 | M31: =Table3[[#This Row],[LineAmount]]-Table3[[#This Row],[TotalCost]] -> 168.138 | N31: =IF(AND(COUNTIFS([0]!OrderID,Table3[[#This Row],[OrderID]],[0]!Category,"hot meal")>0,COUNTIFS([0]!OrderID,Table3[[#This Row],[OrderID]],[0]!Category,"beverage")>0),"combo","single") -> combo | O31: =IF((Table3[[#This Row],[LineAmount]]/(1-Table3[[#This Row],[DiscountPct]]))*Table3[[#This Row],[DiscountPct]]>40,"High Disc","OK") -> High Disc
A32: O00031 | B32: 45872.54 | C32: Plant 1 Canteen | D32: Visitor | E32: UPI | F32: Lunch | G32: 0.06 | H32: =INT($B32) -> 45872 | I32: =IF(COUNTIFS([0]!OrderID,Table3[[#This Row],[OrderID]],[0]!Category,"beverage")>0,"yes","no") -> no | J32: =SUMIFS([0]!LineNetAmount,[0]!OrderID,Table3[[#This Row],[OrderID]]) -> 435.972 | K32: {=_xlfn.TEXTJOIN("+",,_xlfn._xlws.SORT(_xlfn.UNIQUE(_xlfn._xlws.FILTER([0]!Category,[0]!OrderID=Table3[[#This Row],[OrderID]]))))} -> Dessert+Hot Meal | L32: =SUMIFS([0]!FoodCost,[0]!OrderID,Table3[[#This Row],[OrderID]]) -> 232.76 | M32: =Table3[[#This Row],[LineAmount]]-Table3[[#This Row],[TotalCost]] -> 203.212 | N32: =IF(AND(COUNTIFS([0]!OrderID,Table3[[#This Row],[OrderID]],[0]!Category,"hot meal")>0,COUNTIFS([0]!OrderID,Table3[[#This Row],[OrderID]],[0]!Category,"beverage")>0),"combo","single") -> single | O32: =IF((Table3[[#This Row],[LineAmount]]/(1-Table3[[#This Row],[DiscountPct]]))*Table3[[#This Row],[DiscountPct]]>40,"High Disc","OK") -> OK
A33: O00032 | B33: 45888.32 | C33: Plant 2 Canteen | D33: Staff | E33: Cash | F33: Breakfast | G33: 0.12 | H33: =INT($B33) -> 45888 | I33: =IF(COUNTIFS([0]!OrderID,Table3[[#This Row],[OrderID]],[0]!Category,"beverage")>0,"yes","no") -> yes | J33: =SUMIFS([0]!LineNetAmount,[0]!OrderID,Table3[[#This Row],[OrderID]]) -> 466.1888 | K33: {=_xlfn.TEXTJOIN("+",,_xlfn._xlws.SORT(_xlfn.UNIQUE(_xlfn._xlws.FILTER([0]!Category,[0]!OrderID=Table3[[#This Row],[OrderID]]))))} -> Beverage+Dessert+Hot Meal | L33: =SUMIFS([0]!FoodCost,[0]!OrderID,Table3[[#This Row],[OrderID]]) -> 256.44 | M33: =Table3[[#This Row],[LineAmount]]-Table3[[#This Row],[TotalCost]] -> 209.7488 | N33: =IF(AND(COUNTIFS([0]!OrderID,Table3[[#This Row],[OrderID]],[0]!Category,"hot meal")>0,COUNTIFS([0]!OrderID,Table3[[#This Row],[OrderID]],[0]!Category,"beverage")>0),"combo","single") -> combo | O33: =IF((Table3[[#This Row],[LineAmount]]/(1-Table3[[#This Row],[DiscountPct]]))*Table3[[#This Row],[DiscountPct]]>40,"High Disc","OK") -> High Disc
A34: O00033 | B34: 45880.375 | C34: Plant 2 Canteen | D34: Worker | E34: Cash | F34: Breakfast | G34: 0 | H34: =INT($B34) -> 45880 | I34: =IF(COUNTIFS([0]!OrderID,Table3[[#This Row],[OrderID]],[0]!Category,"beverage")>0,"yes","no") -> no | J34: =SUMIFS([0]!LineNetAmount,[0]!OrderID,Table3[[#This Row],[OrderID]]) -> 390.35 | K34: {=_xlfn.TEXTJOIN("+",,_xlfn._xlws.SORT(_xlfn.UNIQUE(_xlfn._xlws.FILTER([0]!Category,[0]!OrderID=Table3[[#This Row],[OrderID]]))))} -> Dessert+Snack | L34: =SUMIFS([0]!FoodCost,[0]!OrderID,Table3[[#This Row],[OrderID]]) -> 162.42 | M34: =Table3[[#This Row],[LineAmount]]-Table3[[#This Row],[TotalCost]] -> 227.93 | N34: =IF(AND(COUNTIFS([0]!OrderID,Table3[[#This Row],[OrderID]],[0]!Category,"hot meal")>0,COUNTIFS([0]!OrderID,Table3[[#This Row],[OrderID]],[0]!Category,"beverage")>0),"combo","single") -> single | O34: =IF((Table3[[#This Row],[LineAmount]]/(1-Table3[[#This Row],[DiscountPct]]))*Table3[[#This Row],[DiscountPct]]>40,"High Disc","OK") -> OK
... A361: O00360 | B361: 45878.689 | C361: Plant 2 Canteen | D361: Visitor | E361: UPI | F361: Dinner | G361: 0.04 | H361: =INT($B361) -> 45878 | I361: =IF(COUNTIFS([0]!OrderID,Table3[[#This Row],[OrderID]],[0]!Category,"beverage")>0,"yes","no") -> yes | J361: =SUMIFS([0]!LineNetAmount,[0]!OrderID,Table3[[#This Row],[OrderID]]) -> 962.1504 | K361: {=_xlfn.TEXTJOIN("+",,_xlfn._xlws.SORT(_xlfn.UNIQUE(_xlfn._xlws.FILTER([0]!Category,[0]!OrderID=Table3[[#This Row],[OrderID]]))))} -> Beverage+Hot Meal | L361: =SUMIFS([0]!FoodCost,[0]!OrderID,Table3[[#This Row],[OrderID]]) -> 466.15 | M361: =Table3[[#This Row],[LineAmount]]-Table3[[#This Row],[TotalCost]] -> 496.0004 | N361: =IF(AND(COUNTIFS([0]!OrderID,Table3[[#This Row],[OrderID]],[0]!Category,"hot meal")>0,COUNTIFS([0]!OrderID,Table3[[#This Row],[OrderID]],[0]!Category,"beverage")>0),"combo","single") -> combo | O361: =IF((Table3[[#This Row],[LineAmount]]/(1-Table3[[#This Row],[DiscountPct]]))*Table3[[#This Row],[DiscountPct]]>40,"High Disc","OK") -> High Disc

Sheet DAY 4 solution
D1: Q 2 | F1: SKU | G1: Revenue | H1: qty | L1: Q 3 | N1: Branch | O1: Total Revenue | P1: total cost | Q1: GM%
F2: HXAJI0 | G2: =SUMIFS(LineNetAmount,SKU,$F2,MonthName,"august") -> 10470.06 | H2: =SUMIFS(Qty,SKU,$F2,MonthName,"august") -> 49 | N2: Head Office Café | O2: =SUMIFS([0]!LineNetAmount,Branch,'DAY 4 solution'!$N2) -> 48982.147 | P2: {=SUMPRODUCT(([0]!Branch='DAY 4 solution'!$N2)*[0]!Qty*UnitCost)} -> 24001.28 | Q2: =(($O2-$P2)/$O2)*100 -> 50.999942
F3: HDPBHS | G3: =SUMIFS(LineNetAmount,SKU,$F3,MonthName,"august") -> 9230.7763 | H3: =SUMIFS(Qty,SKU,$F3,MonthName,"august") -> 38 | N3: Plant 2 Canteen | O3: =SUMIFS([0]!LineNetAmount,Branch,'DAY 4 solution'!$N3) -> 50416.193 | P3: {=SUMPRODUCT(([0]!Branch='DAY 4 solution'!$N3)*[0]!Qty*UnitCost)} -> 24427.5 | Q3: =(($O3-$P3)/$O3)*100 -> 51.548305
F4: HH1DNM | G4: =SUMIFS(LineNetAmount,SKU,$F4,MonthName,"august") -> 8283.3894 | H4: =SUMIFS(Qty,SKU,$F4,MonthName,"august") -> 36 | N4: Plant 1 Canteen | O4: =SUMIFS([0]!LineNetAmount,Branch,'DAY 4 solution'!$N4) -> 33249.291 | P4: {=SUMPRODUCT(([0]!Branch='DAY 4 solution'!$N4)*[0]!Qty*UnitCost)} -> 16720.52 | Q4: =(($O4-$P4)/$O4)*100 -> 49.71165
F5: HUZZPQ | G5: =SUMIFS(LineNetAmount,SKU,$F5,MonthName,"august") -> 6563.112 | H5: =SUMIFS(Qty,SKU,$F5,MonthName,"august") -> 48
F6: H3A3ZM | G6: =SUMIFS(LineNetAmount,SKU,$F6,MonthName,"august") -> 5927.801 | H6: =SUMIFS(Qty,SKU,$F6,MonthName,"august") -> 37
F7: D9T84A | G7: =SUMIFS(LineNetAmount,SKU,$F7,MonthName,"august") -> 4925.456 | H7: =SUMIFS(Qty,SKU,$F7,MonthName,"august") -> 45
F8: DH9SDB | G8: =SUMIFS(LineNetAmount,SKU,$F8,MonthName,"august") -> 3714.9715 | H8: =SUMIFS(Qty,SKU,$F8,MonthName,"august") -> 52
F9: SCKW5N | G9: =SUMIFS(LineNetAmount,SKU,$F9,MonthName,"august") -> 2910.4804 | H9: =SUMIFS(Qty,SKU,$F9,MonthName,"august") -> 44
F10: DFFYVN | G10: =SUMIFS(LineNetAmount,SKU,$F10,MonthName,"august") -> 2362.578 | H10: =SUMIFS(Qty,SKU,$F10,MonthName,"august") -> 46
F11: S5NQ4F | G11: =SUMIFS(LineNetAmount,SKU,$F11,MonthName,"august") -> 2318.778 | H11: =SUMIFS(Qty,SKU,$F11,MonthName,"august") -> 49
F12: DYTJXE | G12: =SUMIFS(LineNetAmount,SKU,$F12,MonthName,"august") -> 2202.3313 | H12: =SUMIFS([0]!Qty,SKU,'DAY 4 solution'!$F13,MonthName,"august") -> 32
F13: SHJ7XV | G13: =SUMIFS(LineNetAmount,SKU,$F13,MonthName,"august") -> 1563.5345 | H13: =SUMIFS([0]!Qty,SKU,'DAY 4 solution'!$F2,MonthName,"august") -> 49
F14: BTIQJ7 | G14: =SUMIFS(LineNetAmount,SKU,$F14,MonthName,"august") -> 1508.5048 | H14: =SUMIFS([0]!Qty,SKU,'DAY 4 solution'!$F3,MonthName,"august") -> 38
F15: SV30T9 | G15: =SUMIFS(LineNetAmount,SKU,$F15,MonthName,"august") -> 1484.1425 | H15: =SUMIFS([0]!Qty,SKU,'DAY 4 solution'!$F19,MonthName,"august") -> 45
F16: BOC6UZ | G16: =SUMIFS(LineNetAmount,SKU,$F16,MonthName,"august") -> 1432.6512 | H16: =SUMIFS([0]!Qty,SKU,'DAY 4 solution'!$F5,MonthName,"august") -> 48
F17: SZBIKC | G17: =SUMIFS(LineNetAmount,SKU,$F17,MonthName,"august") -> 1155.5016 | H17: =SUMIFS([0]!Qty,SKU,'DAY 4 solution'!$F7,MonthName,"august") -> 45
F18: B0T0PV | G18: =SUMIFS(LineNetAmount,SKU,$F18,MonthName,"august") -> 1151.6993 | H18: =SUMIFS([0]!Qty,SKU,'DAY 4 solution'!$F10,MonthName,"august") -> 46
F19: BXO6QJ | G19: =SUMIFS(LineNetAmount,SKU,$F19,MonthName,"august") -> 854.8761 | H19: =SUMIFS([0]!Qty,SKU,'DAY 4 solution'!$F11,MonthName,"august") -> 49
F20: BHL1C3 | G20: =SUMIFS(LineNetAmount,SKU,$F20,MonthName,"august") -> 647.796 | H20: =SUMIFS([0]!Qty,SKU,'DAY 4 solution'!$F12,MonthName,"august") -> 41
A23: Q 1
A24: MonthName | B24: (All)
A26: Row Labels | B26: Total Revenue | C26: % contribution
A27: Beverage | B27: 10321.758 | C27: 0.077813364
A28: Head Office Café | B28: 3489.8727 | C28: 0.33810835
A29: Plant 1 Canteen | B29: 2895.3357 | C29: 0.28050799
A30: Plant 2 Canteen | B30: 3936.5499 | C30: 0.38138365
A31: Dessert | B31: 24556.193 | C31: 0.18512349
A32: Head Office Café | B32: 9544.0172 | C32: 0.3886603
A33: Plant 1 Canteen | B33: 6497.6642 | C33: 0.26460389
A34: Plant 2 Canteen | B34: 8514.5112 | C34: 0.3467358
A35: Hot Meal | B35: 79136.671 | C35: 0.59659317
A36: Head Office Café | B36: 30604.808 | C36: 0.38673358
A37: Plant 1 Canteen | B37: 17407.726 | C37: 0.21997041
A38: Plant 2 Canteen | B38: 31124.138 | C38: 0.39329602
... A43: Grand Total | B43: 132647.63 | C43: 1

Sheet DAY 5 solution
A1: Date | B1: Revenue | C1: Avg Feedback Rating | D1: Avg Waste Cost | E1: Waste Cost
A2: {=_xlfn._xlws.SORT(_xlfn.UNIQUE([0]!OrderDate))} -> 45839 | B2: =SUMIFS([0]!LineNetAmount,OrderDate,'DAY 5 solution'!$A2) -> 198.822 | C2: =IFERROR(AVERAGEIFS([0]!Rating,Feedback!Date,'DAY 5 solution'!$A2),0) -> 3.8571429 | E2: {=SUMPRODUCT(([0]!Date='DAY 5 solution'!$A2)*WasteLog!Qty*WasteLog!$E$2:$E$121)} -> 0
A3: 45840 | B3: =SUMIFS([0]!LineNetAmount,OrderDate,'DAY 5 solution'!$A3) -> 3202.85 | C3: =IFERROR(AVERAGEIFS([0]!Rating,Feedback!Date,'DAY 5 solution'!$A3),0) -> 3.6 | E3: {=SUMPRODUCT(([0]!Date='DAY 5 solution'!$A3)*WasteLog!Qty*WasteLog!$E$2:$E$121)} -> 369.92
A4: 45841 | B4: =SUMIFS([0]!LineNetAmount,OrderDate,'DAY 5 solution'!$A4) -> 1027.7541 | C4: =IFERROR(AVERAGEIFS([0]!Rating,Feedback!Date,'DAY 5 solution'!$A4),0) -> 4 | E4: {=SUMPRODUCT(([0]!Date='DAY 5 solution'!$A4)*WasteLog!Qty*WasteLog!$E$2:$E$121)} -> 0
A5: 45842 | B5: =SUMIFS([0]!LineNetAmount,OrderDate,'DAY 5 solution'!$A5) -> 1622.0684 | C5: =IFERROR(AVERAGEIFS([0]!Rating,Feedback!Date,'DAY 5 solution'!$A5),0) -> 4.5 | E5: {=SUMPRODUCT(([0]!Date='DAY 5 solution'!$A5)*WasteLog!Qty*WasteLog!$E$2:$E$121)} -> 80.92
A6: 45843 | B6: =SUMIFS([0]!LineNetAmount,OrderDate,'DAY 5 solution'!$A6) -> 626.2479 | C6: =IFERROR(AVERAGEIFS([0]!Rating,Feedback!Date,'DAY 5 solution'!$A6),0) -> 4 | E6: {=SUMPRODUCT(([0]!Date='DAY 5 solution'!$A6)*WasteLog!Qty*WasteLog!$E$2:$E$121)} -> 253.64
A7: 45844 | B7: =SUMIFS([0]!LineNetAmount,OrderDate,'DAY 5 solution'!$A7) -> 2758.1276 | C7: =IFERROR(AVERAGEIFS([0]!Rating,Feedback!Date,'DAY 5 solution'!$A7),0) -> 3.5 | E7: {=SUMPRODUCT(([0]!Date='DAY 5 solution'!$A7)*WasteLog!Qty*WasteLog!$E$2:$E$121)} -> 543.5
A8: 45845 | B8: =SUMIFS([0]!LineNetAmount,OrderDate,'DAY 5 solution'!$A8) -> 1619.6286 | C8: =IFERROR(AVERAGEIFS([0]!Rating,Feedback!Date,'DAY 5 solution'!$A8),0) -> 4.75 | E8: {=SUMPRODUCT(([0]!Date='DAY 5 solution'!$A8)*WasteLog!Qty*WasteLog!$E$2:$E$121)} -> 74.07
A9: 45846 | B9: =SUMIFS([0]!LineNetAmount,OrderDate,'DAY 5 solution'!$A9) -> 425.1991 | C9: =IFERROR(AVERAGEIFS([0]!Rating,Feedback!Date,'DAY 5 solution'!$A9),0) -> 4 | E9: {=SUMPRODUCT(([0]!Date='DAY 5 solution'!$A9)*WasteLog!Qty*WasteLog!$E$2:$E$121)} -> 141.28
A10: 45847 | B10: =SUMIFS([0]!LineNetAmount,OrderDate,'DAY 5 solution'!$A10) -> 2706.5737 | C10: =IFERROR(AVERAGEIFS([0]!Rating,Feedback!Date,'DAY 5 solution'!$A10),0) -> 3.1666667 | E10: {=SUMPRODUCT(([0]!Date='DAY 5 solution'!$A10)*WasteLog!Qty*WasteLog!$E$2:$E$121)} -> 111.78
A11: 45848 | B11: =SUMIFS([0]!LineNetAmount,OrderDate,'DAY 5 solution'!$A11) -> 3654.4446 | C11: =IFERROR(AVERAGEIFS([0]!Rating,Feedback!Date,'DAY 5 solution'!$A11),0) -> 4 | E11: {=SUMPRODUCT(([0]!Date='DAY 5 solution'!$A11)*WasteLog!Qty*WasteLog!$E$2:$E$121)} -> 8
A12: 45849 | B12: =SUMIFS([0]!LineNetAmount,OrderDate,'DAY 5 solution'!$A12) -> 3744.4975 | C12: =IFERROR(AVERAGEIFS([0]!Rating,Feedback!Date,'DAY 5 solution'!$A12),0) -> 3.5 | E12: {=SUMPRODUCT(([0]!Date='DAY 5 solution'!$A12)*WasteLog!Qty*WasteLog!$E$2:$E$121)} -> 390.62
A13: 45850 | B13: =SUMIFS([0]!LineNetAmount,OrderDate,'DAY 5 solution'!$A13) -> 3559.4395 | C13: =IFERROR(AVERAGEIFS([0]!Rating,Feedback!Date,'DAY 5 solution'!$A13),0) -> 4 | E13: {=SUMPRODUCT(([0]!Date='DAY 5 solution'!$A13)*WasteLog!Qty*WasteLog!$E$2:$E$121)} -> 143.24
A14: 45851 | B14: =SUMIFS([0]!LineNetAmount,OrderDate,'DAY 5 solution'!$A14) -> 2567.5368 | C14: =IFERROR(AVERAGEIFS([0]!Rating,Feedback!Date,'DAY 5 solution'!$A14),0) -> 3.8 | E14: {=SUMPRODUCT(([0]!Date='DAY 5 solution'!$A14)*WasteLog!Qty*WasteLog!$E$2:$E$121)} -> 0
... A61: 45898 | B61: =SUMIFS([0]!LineNetAmount,OrderDate,'DAY 5 solution'!$A61) -> 1445.0394 | C61: =IFERROR(AVERAGEIFS([0]!Rating,Feedback!Date,'DAY 5 solution'!$A61),0) -> 0 | E61: {=SUMPRODUCT(([0]!Date='DAY 5 solution'!$A61)*WasteLog!Qty*WasteLog!$E$2:$E$121)} -> 0

Sheet DAY 6 solution
B1: SKU | C1: SELECT ANY | D1: VALUE | J1: {=_xlfn.UNIQUE([0]!SKU)} -> SHJ7XV
B2: DH9SDB | C2: UNITcost | D2: =INDEX(orderlinesTABLE[],MATCH(B2,[0]!SKU,0),MATCH('DAY 6 solution'!C2,orderlinesTABLE[#Headers],0)) -> 38.23 | J2: BTIQJ7
J3: DH9SDB
J4: BOC6UZ
J5: H3A3ZM
J6: SZBIKC
J7: HH1DNM
J8: SCKW5N
J9: B0T0PV
J10: BXO6QJ
J11: BHL1C3
J12: DYTJXE
J13: DFFYVN
J14: D9T84A
... J19: S5NQ4F

Sheet OrderLines
A1: OrderID | B1: SKU | C1: Qty | D1: UnitPrice | E1: Category | F1: UnitCost | G1: OrderDate | H1: Branch | I1: DiscountPct | J1: LineNetAmount | K1: MonthName | L1: Shift | M1: PaymentType | N1: ComboFlag | O1: DiscountFlag | P1: totalCOST | Q1: Profit | R1: ItemName | S1: Combination | T1: GM% | U1: FoodCost | W1: DAY 2 SOLUTIONS
A2: O00001 | B2: SHJ7XV | C2: 3 | D2: =VLOOKUP($B2,Menu!$A$1:$F$20,MATCH($D$1,Menu!$A$1:$F$1,0),0) -> 52.45 | E2: =VLOOKUP($B2,Menu!$A$1:$F$20,MATCH(OrderLines!E$1,Menu!$A$1:$F$1,0),0) -> Snack | F2: =VLOOKUP($B2,Menu!$A$1:$F$20,MATCH(OrderLines!F$1,Menu!$A$1:$F$1,0),0) -> 25.8 | G2: =VLOOKUP($A2,Orders!$A$1:$H$361,MATCH($G$1,Orders!$A$1:$H$1,0),0) -> 45852 | H2: =VLOOKUP($A2,Orders!$A$1:$H$361,MATCH(OrderLines!$H$1,Orders!$A$1:$H$1,0),0) -> Head Office Café | I2: =VLOOKUP($A2,Orders!$A$1:$H$361,MATCH(OrderLines!$I$1,Orders!$A$1:$H$1,0),0) -> 0.06 | J2: =$C2*$D2*(1-$I2) -> 147.909 | K2: =TEXT($G2,"mmmm") -> July | L2: =VLOOKUP(OrderLines!$A2,Orders!$A$1:$H$361,MATCH(OrderLines!$L$1,Orders!$A$1:$H$1,0),0) -> Breakfast | M2: =VLOOKUP($A2,Orders!$A$1:$H$361,MATCH(OrderLines!$M$1,Orders!$A$1:$H$1,0),0) -> UPI | N2: =IF(AND(COUNTIFS(OrderID,$A2,Category,"hot meal")>=1,COUNTIFS(OrderID,$A2,Category,"beverage")>=1),"Combo","Single") -> Single | O2: {=IF((SUMPRODUCT((OrderID=OrderLines!$A2)*Qty*UnitPrice*DiscountPct))>40,"HighDisc","OK")} -> OK | P2: =(orderlinesTABLE[[#This Row],[UnitCost]]*orderlinesTABLE[[#This Row],[Qty]]) -> 77.4 | Q2: =(orderlinesTABLE[[#This Row],[LineNetAmount]]-orderlinesTABLE[[#This Row],[totalCOST]]) -> 70.509 | R2: =VLOOKUP($B2,Menu!$A$1:$F$20,MATCH(OrderLines!R$1,Menu!$A$1:$F$1,0),0) -> Poha | S2: {=_xlfn.TEXTJOIN("+",TRUE,_xlfn._xlws.FILTER(orderlinesTABLE[ItemName],OrderID=orderlinesTABLE[[#This Row],[OrderID]]))} -> Poha | T2: =orderlinesTABLE[[#This Row],[Profit]]/orderlinesTABLE[[#This Row],[LineNetAmount]] -> 0.47670527 | U2: =(orderlinesTABLE[[#This Row],[Qty]]*orderlinesTABLE[[#This Row],[UnitCost]]) -> 77.4
A3: O00002 | B3: BTIQJ7 | C3: 1 | D3: =VLOOKUP($B3,Menu!$A$1:$F$20,MATCH($D$1,Menu!$A$1:$F$1,0),0) -> 30.34 | E3: =VLOOKUP($B3,Menu!$A$1:$F$20,MATCH(OrderLines!E$1,Menu!$A$1:$F$1,0),0) -> Beverage | F3: =VLOOKUP($B3,Menu!$A$1:$F$20,MATCH(OrderLines!F$1,Menu!$A$1:$F$1,0),0) -> 14.18 | G3: =VLOOKUP($A3,Orders!$A$1:$H$361,MATCH($G$1,Orders!$A$1:$H$1,0),0) -> 45862 | H3: =VLOOKUP($A3,Orders!$A$1:$H$361,MATCH(OrderLines!$H$1,Orders!$A$1:$H$1,0),0) -> Plant 2 Canteen | I3: =VLOOKUP($A3,Orders!$A$1:$H$361,MATCH(OrderLines!$I$1,Orders!$A$1:$H$1,0),0) -> 0.05 | J3: =$C3*$D3*(1-$I3) -> 28.823 | K3: =TEXT($G3,"mmmm") -> July | L3: =VLOOKUP(OrderLines!$A3,Orders!$A$1:$H$361,MATCH(OrderLines!$L$1,Orders!$A$1:$H$1,0),0) -> Dinner | M3: =VLOOKUP($A3,Orders!$A$1:$H$361,MATCH(OrderLines!$M$1,Orders!$A$1:$H$1,0),0) -> Cash | N3: =IF(AND(COUNTIFS(OrderID,$A3,Category,"hot meal")>=1,COUNTIFS(OrderID,$A3,Category,"beverage")>=1),"Combo","Single") -> Single | O3: {=IF((SUMPRODUCT((OrderID=OrderLines!$A3)*Qty*UnitPrice*DiscountPct))>40,"HighDisc","OK")} -> OK | P3: =(orderlinesTABLE[[#This Row],[UnitCost]]*orderlinesTABLE[[#This Row],[Qty]]) -> 14.18 | Q3: =(orderlinesTABLE[[#This Row],[LineNetAmount]]-orderlinesTABLE[[#This Row],[totalCOST]]) -> 14.643 | R3: =VLOOKUP($B3,Menu!$A$1:$F$20,MATCH(OrderLines!R$1,Menu!$A$1:$F$1,0),0) -> Tea | S3: {=_xlfn.TEXTJOIN("+",TRUE,_xlfn._xlws.FILTER(orderlinesTABLE[ItemName],OrderID=orderlinesTABLE[[#This Row],[OrderID]]))} -> Tea+Gulab Jamun (2 pc) | T3: =orderlinesTABLE[[#This Row],[Profit]]/orderlinesTABLE[[#This Row],[LineNetAmount]] -> 0.50803178 | U3: =(orderlinesTABLE[[#This Row],[Qty]]*orderlinesTABLE[[#This Row],[UnitCost]]) -> 14.18
A4: O00002 | B4: DH9SDB | C4: 1 | D4: =VLOOKUP($B4,Menu!$A$1:$F$20,MATCH($D$1,Menu!$A$1:$F$1,0),0) -> 76.55 | E4: =VLOOKUP($B4,Menu!$A$1:$F$20,MATCH(OrderLines!E$1,Menu!$A$1:$F$1,0),0) -> Dessert | F4: =VLOOKUP($B4,Menu!$A$1:$F$20,MATCH(OrderLines!F$1,Menu!$A$1:$F$1,0),0) -> 38.23 | G4: =VLOOKUP($A4,Orders!$A$1:$H$361,MATCH($G$1,Orders!$A$1:$H$1,0),0) -> 45862 | H4: =VLOOKUP($A4,Orders!$A$1:$H$361,MATCH(OrderLines!$H$1,Orders!$A$1:$H$1,0),0) -> Plant 2 Canteen | I4: =VLOOKUP($A4,Orders!$A$1:$H$361,MATCH(OrderLines!$I$1,Orders!$A$1:$H$1,0),0) -> 0.05 | J4: =$C4*$D4*(1-$I4) -> 72.7225 | K4: =TEXT($G4,"mmmm") -> July | L4: =VLOOKUP(OrderLines!$A4,Orders!$A$1:$H$361,MATCH(OrderLines!$L$1,Orders!$A$1:$H$1,0),0) -> Dinner | M4: =VLOOKUP($A4,Orders!$A$1:$H$361,MATCH(OrderLines!$M$1,Orders!$A$1:$H$1,0),0) -> Cash | N4: =IF(AND(COUNTIFS(OrderID,$A4,Category,"hot meal")>=1,COUNTIFS(OrderID,$A4,Category,"beverage")>=1),"Combo","Single") -> Single | O4: {=IF((SUMPRODUCT((OrderID=OrderLines!$A4)*Qty*UnitPrice*DiscountPct))>40,"HighDisc","OK")} -> OK | P4: =(orderlinesTABLE[[#This Row],[UnitCost]]*orderlinesTABLE[[#This Row],[Qty]]) -> 38.23 | Q4: =(orderlinesTABLE[[#This Row],[LineNetAmount]]-orderlinesTABLE[[#This Row],[totalCOST]]) -> 34.4925 | R4: =VLOOKUP($B4,Menu!$A$1:$F$20,MATCH(OrderLines!R$1,Menu!$A$1:$F$1,0),0) -> Gulab Jamun (2 pc) | S4: {=_xlfn.TEXTJOIN("+",TRUE,_xlfn._xlws.FILTER(orderlinesTABLE[ItemName],OrderID=orderlinesTABLE[[#This Row],[OrderID]]))} -> Tea+Gulab Jamun (2 pc) | T4: =orderlinesTABLE[[#This Row],[Profit]]/orderlinesTABLE[[#This Row],[LineNetAmount]] -> 0.474303 | U4: =(orderlinesTABLE[[#This Row],[Qty]]*orderlinesTABLE[[#This Row],[UnitCost]]) -> 38.23 | Y4: Sum of LineNetAmount
A5: O00003 | B5: BOC6UZ | C5: 2 | D5: =VLOOKUP($B5,Menu!$A$1:$F$20,MATCH($D$1,Menu!$A$1:$F$1,0),0) -> 32.98 | E5: =VLOOKUP($B5,Menu!$A$1:$F$20,MATCH(OrderLines!E$1,Menu!$A$1:$F$1,0),0) -> Beverage | F5: =VLOOKUP($B5,Menu!$A$1:$F$20,MATCH(OrderLines!F$1,Menu!$A$1:$F$1,0),0) -> 11.84 | G5: =VLOOKUP($A5,Orders!$A$1:$H$361,MATCH($G$1,Orders!$A$1:$H$1,0),0) -> 45848 | H5: =VLOOKUP($A5,Orders!$A$1:$H$361,MATCH(OrderLines!$H$1,Orders!$A$1:$H$1,0),0) -> Head Office Café | I5: =VLOOKUP($A5,Orders!$A$1:$H$361,MATCH(OrderLines!$I$1,Orders!$A$1:$H$1,0),0) -> 0 | J5: =$C5*$D5*(1-$I5) -> 65.96 | K5: =TEXT($G5,"mmmm") -> July | L5: =VLOOKUP(OrderLines!$A5,Orders!$A$1:$H$361,MATCH(OrderLines!$L$1,Orders!$A$1:$H$1,0),0) -> Lunch | M5: =VLOOKUP($A5,Orders!$A$1:$H$361,MATCH(OrderLines!$M$1,Orders!$A$1:$H$1,0),0) -> Card | N5: =IF(AND(COUNTIFS(OrderID,$A5,Category,"hot meal")>=1,COUNTIFS(OrderID,$A5,Category,"beverage")>=1),"Combo","Single") -> Combo | O5: {=IF((SUMPRODUCT((OrderID=OrderLines!$A5)*Qty*UnitPrice*DiscountPct))>40,"HighDisc","OK")} -> OK | P5: =(orderlinesTABLE[[#This Row],[UnitCost]]*orderlinesTABLE[[#This Row],[Qty]]) -> 23.68 | Q5: =(orderlinesTABLE[[#This Row],[LineNetAmount]]-orderlinesTABLE[[#This Row],[totalCOST]]) -> 42.28 | R5: =VLOOKUP($B5,Menu!$A$1:$F$20,MATCH(OrderLines!R$1,Menu!$A$1:$F$1,0),0) -> Masala Chaas | S5: {=_xlfn.TEXTJOIN("+",TRUE,_xlfn._xlws.FILTER(orderlinesTABLE[ItemName],OrderID=orderlinesTABLE[[#This Row],[OrderID]]))} -> Masala Chaas+Poha+Paneer Butter Masala + Naan+Paneer Roll | T5: =orderlinesTABLE[[#This Row],[Profit]]/orderlinesTABLE[[#This Row],[LineNetAmount]] -> 0.64099454 | U5: =(orderlinesTABLE[[#This Row],[Qty]]*orderlinesTABLE[[#This Row],[UnitCost]]) -> 23.68 | Y5: 132647.63
A6: O00003 | B6: SHJ7XV | C6: 1 | D6: =VLOOKUP($B6,Menu!$A$1:$F$20,MATCH($D$1,Menu!$A$1:$F$1,0),0) -> 52.45 | E6: =VLOOKUP($B6,Menu!$A$1:$F$20,MATCH(OrderLines!E$1,Menu!$A$1:$F$1,0),0) -> Snack | F6: =VLOOKUP($B6,Menu!$A$1:$F$20,MATCH(OrderLines!F$1,Menu!$A$1:$F$1,0),0) -> 25.8 | G6: =VLOOKUP($A6,Orders!$A$1:$H$361,MATCH($G$1,Orders!$A$1:$H$1,0),0) -> 45848 | H6: =VLOOKUP($A6,Orders!$A$1:$H$361,MATCH(OrderLines!$H$1,Orders!$A$1:$H$1,0),0) -> Head Office Café | I6: =VLOOKUP($A6,Orders!$A$1:$H$361,MATCH(OrderLines!$I$1,Orders!$A$1:$H$1,0),0) -> 0 | J6: =$C6*$D6*(1-$I6) -> 52.45 | K6: =TEXT($G6,"mmmm") -> July | L6: =VLOOKUP(OrderLines!$A6,Orders!$A$1:$H$361,MATCH(OrderLines!$L$1,Orders!$A$1:$H$1,0),0) -> Lunch | M6: =VLOOKUP($A6,Orders!$A$1:$H$361,MATCH(OrderLines!$M$1,Orders!$A$1:$H$1,0),0) -> Card | N6: =IF(AND(COUNTIFS(OrderID,$A6,Category,"hot meal")>=1,COUNTIFS(OrderID,$A6,Category,"beverage")>=1),"Combo","Single") -> Combo | O6: {=IF((SUMPRODUCT((OrderID=OrderLines!$A6)*Qty*UnitPrice*DiscountPct))>40,"HighDisc","OK")} -> OK | P6: =(orderlinesTABLE[[#This Row],[UnitCost]]*orderlinesTABLE[[#This Row],[Qty]]) -> 25.8 | Q6: =(orderlinesTABLE[[#This Row],[LineNetAmount]]-orderlinesTABLE[[#This Row],[totalCOST]]) -> 26.65 | R6: =VLOOKUP($B6,Menu!$A$1:$F$20,MATCH(OrderLines!R$1,Menu!$A$1:$F$1,0),0) -> Poha | S6: {=_xlfn.TEXTJOIN("+",TRUE,_xlfn._xlws.FILTER(orderlinesTABLE[ItemName],OrderID=orderlinesTABLE[[#This Row],[OrderID]]))} -> Masala Chaas+Poha+Paneer Butter Masala + Naan+Paneer Roll | T6: =orderlinesTABLE[[#This Row],[Profit]]/orderlinesTABLE[[#This Row],[LineNetAmount]] -> 0.50810296 | U6: =(orderlinesTABLE[[#This Row],[Qty]]*orderlinesTABLE[[#This Row],[UnitCost]]) -> 25.8
A7: O00003 | B7: H3A3ZM | C7: 3 | D7: =VLOOKUP($B7,Menu!$A$1:$F$20,MATCH($D$1,Menu!$A$1:$F$1,0),0) -> 170.83 | E7: =VLOOKUP($B7,Menu!$A$1:$F$20,MATCH(OrderLines!E$1,Menu!$A$1:$F$1,0),0) -> Hot Meal | F7: =VLOOKUP($B7,Menu!$A$1:$F$20,MATCH(OrderLines!F$1,Menu!$A$1:$F$1,0),0) -> 74.07 | G7: =VLOOKUP($A7,Orders!$A$1:$H$361,MATCH($G$1,Orders!$A$1:$H$1,0),0) -> 45848 | H7: =VLOOKUP($A7,Orders!$A$1:$H$361,MATCH(OrderLines!$H$1,Orders!$A$1:$H$1,0),0) -> Head Office Café | I7: =VLOOKUP($A7,Orders!$A$1:$H$361,MATCH(OrderLines!$I$1,Orders!$A$1:$H$1,0),0) -> 0 | J7: =$C7*$D7*(1-$I7) -> 512.49 | K7: =TEXT($G7,"mmmm") -> July | L7: =VLOOKUP(OrderLines!$A7,Orders!$A$1:$H$361,MATCH(OrderLines!$L$1,Orders!$A$1:$H$1,0),0) -> Lunch | M7: =VLOOKUP($A7,Orders!$A$1:$H$361,MATCH(OrderLines!$M$1,Orders!$A$1:$H$1,0),0) -> Card | N7: =IF(AND(COUNTIFS(OrderID,$A7,Category,"hot meal")>=1,COUNTIFS(OrderID,$A7,Category,"beverage")>=1),"Combo","Single") -> Combo | O7: {=IF((SUMPRODUCT((OrderID=OrderLines!$A7)*Qty*UnitPrice*DiscountPct))>40,"HighDisc","OK")} -> OK | P7: =(orderlinesTABLE[[#This Row],[UnitCost]]*orderlinesTABLE[[#This Row],[Qty]]) -> 222.21 | Q7: =(orderlinesTABLE[[#This Row],[LineNetAmount]]-orderlinesTABLE[[#This Row],[totalCOST]]) -> 290.28 | R7: =VLOOKUP($B7,Menu!$A$1:$F$20,MATCH(OrderLines!R$1,Menu!$A$1:$F$1,0),0) -> Paneer Butter Masala + Naan | S7: {=_xlfn.TEXTJOIN("+",TRUE,_xlfn._xlws.FILTER(orderlinesTABLE[ItemName],OrderID=orderlinesTABLE[[#This Row],[OrderID]]))} -> Masala Chaas+Poha+Paneer Butter Masala + Naan+Paneer Roll | T7: =orderlinesTABLE[[#This Row],[Profit]]/orderlinesTABLE[[#This Row],[LineNetAmount]] -> 0.56641105 | U7: =(orderlinesTABLE[[#This Row],[Qty]]*orderlinesTABLE[[#This Row],[UnitCost]]) -> 222.21
A8: O00003 | B8: SZBIKC | C8: 1 | D8: =VLOOKUP($B8,Menu!$A$1:$F$20,MATCH($D$1,Menu!$A$1:$F$1,0),0) -> 38.06 | E8: =VLOOKUP($B8,Menu!$A$1:$F$20,MATCH(OrderLines!E$1,Menu!$A$1:$F$1,0),0) -> Snack | F8: =VLOOKUP($B8,Menu!$A$1:$F$20,MATCH(OrderLines!F$1,Menu!$A$1:$F$1,0),0) -> 19.55 | G8: =VLOOKUP($A8,Orders!$A$1:$H$361,MATCH($G$1,Orders!$A$1:$H$1,0),0) -> 45848 | H8: =VLOOKUP($A8,Orders!$A$1:$H$361,MATCH(OrderLines!$H$1,Orders!$A$1:$H$1,0),0) -> Head Office Café | I8: =VLOOKUP($A8,Orders!$A$1:$H$361,MATCH(OrderLines!$I$1,Orders!$A$1:$H$1,0),0) -> 0 | J8: =$C8*$D8*(1-$I8) -> 38.06 | K8: =TEXT($G8,"mmmm") -> July | L8: =VLOOKUP(OrderLines!$A8,Orders!$A$1:$H$361,MATCH(OrderLines!$L$1,Orders!$A$1:$H$1,0),0) -> Lunch | M8: =VLOOKUP($A8,Orders!$A$1:$H$361,MATCH(OrderLines!$M$1,Orders!$A$1:$H$1,0),0) -> Card | N8: =IF(AND(COUNTIFS(OrderID,$A8,Category,"hot meal")>=1,COUNTIFS(OrderID,$A8,Category,"beverage")>=1),"Combo","Single") -> Combo | O8: {=IF((SUMPRODUCT((OrderID=OrderLines!$A8)*Qty*UnitPrice*DiscountPct))>40,"HighDisc","OK")} -> OK | P8: =(orderlinesTABLE[[#This Row],[UnitCost]]*orderlinesTABLE[[#This Row],[Qty]]) -> 19.55 | Q8: =(orderlinesTABLE[[#This Row],[LineNetAmount]]-orderlinesTABLE[[#This Row],[totalCOST]]) -> 18.51 | R8: =VLOOKUP($B8,Menu!$A$1:$F$20,MATCH(OrderLines!R$1,Menu!$A$1:$F$1,0),0) -> Paneer Roll | S8: {=_xlfn.TEXTJOIN("+",TRUE,_xlfn._xlws.FILTER(orderlinesTABLE[ItemName],OrderID=orderlinesTABLE[[#This Row],[OrderID]]))} -> Masala Chaas+Poha+Paneer Butter Masala + Naan+Paneer Roll | T8: =orderlinesTABLE[[#This Row],[Profit]]/orderlinesTABLE[[#This Row],[LineNetAmount]] -> 0.48633736 | U8: =(orderlinesTABLE[[#This Row],[Qty]]*orderlinesTABLE[[#This Row],[UnitCost]]) -> 19.55
A9: O00004 | B9: HH1DNM | C9: 2 | D9: =VLOOKUP($B9,Menu!$A$1:$F$20,MATCH($D$1,Menu!$A$1:$F$1,0),0) -> 246.09 | E9: =VLOOKUP($B9,Menu!$A$1:$F$20,MATCH(OrderLines!E$1,Menu!$A$1:$F$1,0),0) -> Hot Meal | F9: =VLOOKUP($B9,Menu!$A$1:$F$20,MATCH(OrderLines!F$1,Menu!$A$1:$F$1,0),0) -> 112.08 | G9: =VLOOKUP($A9,Orders!$A$1:$H$361,MATCH($G$1,Orders!$A$1:$H$1,0),0) -> 45879 | H9: =VLOOKUP($A9,Orders!$A$1:$H$361,MATCH(OrderLines!$H$1,Orders!$A$1:$H$1,0),0) -> Plant 2 Canteen | I9: =VLOOKUP($A9,Orders!$A$1:$H$361,MATCH(OrderLines!$I$1,Orders!$A$1:$H$1,0),0) -> 0.03 | J9: =$C9*$D9*(1-$I9) -> 477.4146 | K9: =TEXT($G9,"mmmm") -> August | L9: =VLOOKUP(OrderLines!$A9,Orders!$A$1:$H$361,MATCH(OrderLines!$L$1,Orders!$A$1:$H$1,0),0) -> Breakfast | M9: =VLOOKUP($A9,Orders!$A$1:$H$361,MATCH(OrderLines!$M$1,Orders!$A$1:$H$1,0),0) -> Cash | N9: =IF(AND(COUNTIFS(OrderID,$A9,Category,"hot meal")>=1,COUNTIFS(OrderID,$A9,Category,"beverage")>=1),"Combo","Single") -> Single | O9: {=IF((SUMPRODUCT((OrderID=OrderLines!$A9)*Qty*UnitPrice*DiscountPct))>40,"HighDisc","OK")} -> OK | P9: =(orderlinesTABLE[[#This Row],[UnitCost]]*orderlinesTABLE[[#This Row],[Qty]]) -> 224.16 | Q9: =(orderlinesTABLE[[#This Row],[LineNetAmount]]-orderlinesTABLE[[#This Row],[totalCOST]]) -> 253.2546 | R9: =VLOOKUP($B9,Menu!$A$1:$F$20,MATCH(OrderLines!R$1,Menu!$A$1:$F$1,0),0) -> Egg Curry + Rice | S9: {=_xlfn.TEXTJOIN("+",TRUE,_xlfn._xlws.FILTER(orderlinesTABLE[ItemName],OrderID=orderlinesTABLE[[#This Row],[OrderID]]))} -> Egg Curry + Rice | T9: =orderlinesTABLE[[#This Row],[Profit]]/orderlinesTABLE[[#This Row],[LineNetAmount]] -> 0.530471 | U9: =(orderlinesTABLE[[#This Row],[Qty]]*orderlinesTABLE[[#This Row],[UnitCost]]) -> 224.16
